Workbook

Sheet Resumo
A1: COTAÇÃO DE PREÇOS DE REFERÊNCIA – SERVIÇOS ESPECIALIZADOS EM SAÚDE EM UNIDADES MÓVEIS (Carretas)
A2: Pesquisa de preços – credenciamento de serviços especializados em saúde por meio de unidades móveis (Lei nº 14.133/2021, art. 23).
A3: Data da pesquisa: 07/10/2026. Valores em reais (R$), com todos os custos de mobilização, instalação, operação, equipe, insumos e laudos inclusos (TR, item 2.3.3).
A5: Lote | B5: Valor estimado do lote (R$)
A6: Lote 1 – Mamografia bilateral digital | B6: ='Lote 1 - Mamografia'!V4 -> 4615986
A7: Lote 2 – Consultas médicas especializadas | B7: ='Lote 2 - Consultas'!V18 -> 22868454
A8: Lote 3 – Exames diagnósticos | B8: ='Lote 3 - Exames'!V12 -> 17203714
A9: Lote 4 – Ressonância magnética | B9: ='Lote 4 - Ressonancia'!V5 -> 11851030
A10: Lote 5 – Atendimentos e procedimentos odontológicos | B10: ='Lote 5 - Odontologia'!V67 -> 20579183
A11: VALOR GLOBAL ESTIMADO | B11: =SUM(B6:B10) -> 77118366
A13: Metodologia: para cada item foram reunidos até três preços de contratações públicas (credenciamentos, pregões, atas de registro de preços, contratos e tabelas de credenciamento de órgãos e consórcios públicos), indicados nas colunas Fonte/Valor/Link de cada lote. O valor unitário de referência de cada item corresponde à MEDIANA dos preços coletados (Lei nº 14.133/2021, art. 23; IN SEGES/ME nº 65/2021, art. 6º), apresentada ao lado do menor preço, da média e do maior preço. Para os serviços com correspondente na Tabela de Serviços de Saúde executados em unidades móveis/itinerantes do ICISMEP (TSPS 2026), a mediana foi confrontada com o valor ICISMEP (coluna de diferença percentual), demonstrando que o valor de referência resultante das cotações é inferior ao praticado por aquele consórcio para o mesmo serviço. Itens marcados como 'análogo' usam procedimento equivalente quando não havia o item idêntico na fonte. Itens com menos de três preços estão sujeitos à justificativa prevista no art. 6º, §5º, da IN SEGES/ME nº 65/2021. Os quantitativos são estimativas do TR e não geram obrigação de execução.

Sheet Lote 1 - Mamografia
A1: LOTE 1 – EXAMES DE MAMOGRAFIA BILATERAL (unidade móvel)
A2: Item | B2: Descrição | C2: Unid. | D2: Qtd. estimada | E2: Fonte 1 | F2: Valor 1 (R$) | G2: Link 1 | H2: Fonte 2 | I2: Valor 2 (R$) | J2: Link 2 | K2: Fonte 3 | L2: Valor 3 (R$) | M2: Link 3 | N2: Menor (R$) | O2: Média (R$) | P2: Mediana (R$) | Q2: Maior (R$) | R2: Valor ICISMEP – TSPS 2026, serviço em unidade móvel/itinerante (R$) | S2: Teto de verificação: ICISMEP − 4% (R$) | T2: Valor unit. referência (R$) | U2: Diferença ref. x ICISMEP (%) | V2: Valor total estimado (R$)
A3: 1 | B3: Exame de MAMOGRAFIA BILATERAL DIGITAL para rastreamento e/ou diagnóstico, em unidade móvel temporária | C3: Exame | D3: 34600 | E3: CIS Circuito das Águas/MG – Credenciamento 04/2025 (Proc. 054/2025), carreta itinerante | F3: 80 | G3: https://pncp.gov.br/pncp-api/v1/orgaos/71203715000190/compras/2026/1/arquivos/1 | H3: CIMINAS/MG – Termo de Contrato 741/2025 (Credenciamento 040/2025 – Sistema Carretas da Saúde), 30/09/2025 (pacote básico de mamografia em carreta (triagem + consulta ginecológica + mamografia bilateral com laudo)) | I3: 133.41 | J3: https://ciminas.mg.gov.br | K3: ICISMEP/MG – TSPS jan/2026, atualização II (Unidade Móvel Saúde da Mulher) (mamografia em unidade móvel) | L3: 140.45 | M3: https://icismep.mg.gov.br/wp-content/uploads/2026/02/03.-TSPS-JANEIRO-DE-2026-ATUALIZACAO-II-1.pdf | N3: =IF(COUNT(F3,I3,L3)=0,"",MIN(F3,I3,L3)) -> 80 | O3: =IF(COUNT(F3,I3,L3)=0,"",AVERAGE(F3,I3,L3)) -> 117.95333 | P3: =IF(COUNT(F3,I3,L3)=0,"",MEDIAN(F3,I3,L3)) -> 133.41 | Q3: =IF(COUNT(F3,I3,L3)=0,"",MAX(F3,I3,L3)) -> 140.45 | R3: 140.45 | S3: =IF(ISNUMBER(R3),ROUNDDOWN(R3*0.96,2),"—") -> 134.83 | T3: =IF(COUNT(F3,I3,L3)=0,"Sem cotação",ROUND(P3,2)) -> 133.41 | U3: =IF(AND(ISNUMBER(R3),ISNUMBER(T3)),T3/R3-1,"—") -> -0.0501246 | V3: =IF(ISNUMBER(T3),D3*T3,0) -> 4615986
B4: SUBTOTAL DO LOTE | V4: =SUM(V3:V3) -> 4615986

Sheet Lote 2 - Consultas
A1: LOTE 2 – CONSULTAS MÉDICAS ESPECIALIZADAS (unidade móvel)
A2: Item | B2: Descrição | C2: Unid. | D2: Qtd. estimada | E2: Fonte 1 | F2: Valor 1 (R$) | G2: Link 1 | H2: Fonte 2 | I2: Valor 2 (R$) | J2: Link 2 | K2: Fonte 3 | L2: Valor 3 (R$) | M2: Link 3 | N2: Menor (R$) | O2: Média (R$) | P2: Mediana (R$) | Q2: Maior (R$) | R2: Valor ICISMEP – TSPS 2026, serviço em unidade móvel/itinerante (R$) | S2: Teto de verificação: ICISMEP − 4% (R$) | T2: Valor unit. referência (R$) | U2: Diferença ref. x ICISMEP (%) | V2: Valor total estimado (R$)
A3: 1 | B3: Consulta especializada na área de ORTOPEDIA, em unidade móvel temporária | C3: Consulta | D3: 43440 | E3: SESA/ES – Credenciamento SRSV/NRA 001/2026 (consulta médica especializada adulto) | F3: 50 | G3: https://saude.es.gov.br/Media/sesa/Credenciamento/EDITAL%20SESA-SRSV-NRA%20001-26.pdf | H3: CISAME/MG – Tabela de Preços e Serviços 2026 (Credenciamento 01/2025, Contrato 10/2026) | I3: 92.48 | J3: https://www.cisame.mg.gov.br/compliance/tabela-de-precos-e-servicos/ | K3: Pref. Iuiú/BA – Edital de Credenciamento 022/2026 | L3: 100 | M3: https://www.procede.api.br/publica/documentos/PRYXAMTCDSCNU-20260528-145706--!--CREDENCIAMENTO_MEDICOS_EDITAL_2026.pdf | N3: =IF(COUNT(F3,I3,L3)=0,"",MIN(F3,I3,L3)) -> 50 | O3: =IF(COUNT(F3,I3,L3)=0,"",AVERAGE(F3,I3,L3)) -> 80.826667 | P3: =IF(COUNT(F3,I3,L3)=0,"",MEDIAN(F3,I3,L3)) -> 92.48 | Q3: =IF(COUNT(F3,I3,L3)=0,"",MAX(F3,I3,L3)) -> 100 | R3: 250 | S3: =IF(ISNUMBER(R3),ROUNDDOWN(R3*0.96,2),"—") -> 240 | T3: =IF(COUNT(F3,I3,L3)=0,"Sem cotação",ROUND(P3,2)) -> 92.48 | U3: =IF(AND(ISNUMBER(R3),ISNUMBER(T3)),T3/R3-1,"—") -> -0.63008 | V3: =IF(ISNUMBER(T3),D3*T3,0) -> 4017331.2
A4: 2 | B4: Consulta especializada na área de DERMATOLOGIA, em unidade móvel temporária | C4: Consulta | D4: 29865 | E4: SESA/ES – Credenciamento SRSV/NRA 001/2026 (consulta médica especializada adulto) | F4: 50 | G4: https://saude.es.gov.br/Media/sesa/Credenciamento/EDITAL%20SESA-SRSV-NRA%20001-26.pdf | H4: CISAME/MG – Tabela de Preços e Serviços 2026 (Credenciamento 01/2025, Contrato 10/2026) | I4: 97.63 | J4: https://www.cisame.mg.gov.br/compliance/tabela-de-precos-e-servicos/ | K4: Pref. Três Lagoas/MS – Edital de Credenciamento 002/2026 (valor único para todas as especialidades) | L4: 115 | M4: https://www.treslagoas.ms.gov.br/prefeitura-de-tres-lagoas-amplia-acesso-a-consultas-especializadas-com-novo-credenciamento-na-saude/ | N4: =IF(COUNT(F4,I4,L4)=0,"",MIN(F4,I4,L4)) -> 50 | O4: =IF(COUNT(F4,I4,L4)=0,"",AVERAGE(F4,I4,L4)) -> 87.543333 | P4: =IF(COUNT(F4,I4,L4)=0,"",MEDIAN(F4,I4,L4)) -> 97.63 | Q4: =IF(COUNT(F4,I4,L4)=0,"",MAX(F4,I4,L4)) -> 115 | R4: 250 | S4: =IF(ISNUMBER(R4),ROUNDDOWN(R4*0.96,2),"—") -> 240 | T4: =IF(COUNT(F4,I4,L4)=0,"Sem cotação",ROUND(P4,2)) -> 97.63 | U4: =IF(AND(ISNUMBER(R4),ISNUMBER(T4)),T4/R4-1,"—") -> -0.60948 | V4: =IF(ISNUMBER(T4),D4*T4,0) -> 2915720
A5: 3 | B5: Consulta especializada na área de NEUROLOGIA, em unidade móvel temporária | C5: Consulta | D5: 24435 | E5: SESA/ES – Credenciamento SRSV/NRA 001/2026 (consulta neurologia) | F5: 75 | G5: https://saude.es.gov.br/Media/sesa/Credenciamento/EDITAL%20SESA-SRSV-NRA%20001-26.pdf | H5: CISAMUSEP/PR – Tabela 2026 (12/06/2026) | I5: 100 | J5: https://cisamusep.org.br/uploads/pagina/arquivos/Tabela-Cisamusep-1206.pdf | K5: CISAME/MG – Tabela de Preços e Serviços 2026 (Credenciamento 01/2025, Contrato 10/2026) | L5: 125.24 | M5: https://www.cisame.mg.gov.br/compliance/tabela-de-precos-e-servicos/ | N5: =IF(COUNT(F5,I5,L5)=0,"",MIN(F5,I5,L5)) -> 75 | O5: =IF(COUNT(F5,I5,L5)=0,"",AVERAGE(F5,I5,L5)) -> 100.08 | P5: =IF(COUNT(F5,I5,L5)=0,"",MEDIAN(F5,I5,L5)) -> 100 | Q5: =IF(COUNT(F5,I5,L5)=0,"",MAX(F5,I5,L5)) -> 125.24 | R5: 250 | S5: =IF(ISNUMBER(R5),ROUNDDOWN(R5*0.96,2),"—") -> 240 | T5: =IF(COUNT(F5,I5,L5)=0,"Sem cotação",ROUND(P5,2)) -> 100 | U5: =IF(AND(ISNUMBER(R5),ISNUMBER(T5)),T5/R5-1,"—") -> -0.6 | V5: =IF(ISNUMBER(T5),D5*T5,0) -> 2443500
A6: 4 | B6: Consulta especializada na área de ENDOCRINOLOGIA, em unidade móvel temporária | C6: Consulta | D6: 21720 | E6: SESA/ES – Credenciamento SRSV/NRA 001/2026 (consulta médica especializada adulto) | F6: 50 | G6: https://saude.es.gov.br/Media/sesa/Credenciamento/EDITAL%20SESA-SRSV-NRA%20001-26.pdf | H6: CISAME/MG – Tabela de Preços e Serviços 2026 (Credenciamento 01/2025, Contrato 10/2026) | I6: 114.97 | J6: https://www.cisame.mg.gov.br/compliance/tabela-de-precos-e-servicos/ | K6: Pref. Três Lagoas/MS – Edital de Credenciamento 002/2026 (valor único para todas as especialidades) | L6: 115 | M6: https://www.treslagoas.ms.gov.br/prefeitura-de-tres-lagoas-amplia-acesso-a-consultas-especializadas-com-novo-credenciamento-na-saude/ | N6: =IF(COUNT(F6,I6,L6)=0,"",MIN(F6,I6,L6)) -> 50 | O6: =IF(COUNT(F6,I6,L6)=0,"",AVERAGE(F6,I6,L6)) -> 93.323333 | P6: =IF(COUNT(F6,I6,L6)=0,"",MEDIAN(F6,I6,L6)) -> 114.97 | Q6: =IF(COUNT(F6,I6,L6)=0,"",MAX(F6,I6,L6)) -> 115 | R6: 250 | S6: =IF(ISNUMBER(R6),ROUNDDOWN(R6*0.96,2),"—") -> 240 | T6: =IF(COUNT(F6,I6,L6)=0,"Sem cotação",ROUND(P6,2)) -> 114.97 | U6: =IF(AND(ISNUMBER(R6),ISNUMBER(T6)),T6/R6-1,"—") -> -0.54012 | V6: =IF(ISNUMBER(T6),D6*T6,0) -> 2497148.4
A7: 5 | B7: Consulta especializada na área de GINECOLOGIA, em unidade móvel temporária | C7: Consulta | D7: 21720 | E7: SESA/ES – Credenciamento SRSV/NRA 001/2026 (consulta médica especializada adulto) | F7: 50 | G7: https://saude.es.gov.br/Media/sesa/Credenciamento/EDITAL%20SESA-SRSV-NRA%20001-26.pdf | H7: CISAME/MG – Tabela de Preços e Serviços 2026 (Credenciamento 01/2025, Contrato 10/2026) | I7: 96.5 | J7: https://www.cisame.mg.gov.br/compliance/tabela-de-precos-e-servicos/ | K7: Pref. Iuiú/BA – Edital de Credenciamento 022/2026 | L7: 161.67 | M7: https://www.procede.api.br/publica/documentos/PRYXAMTCDSCNU-20260528-145706--!--CREDENCIAMENTO_MEDICOS_EDITAL_2026.pdf | N7: =IF(COUNT(F7,I7,L7)=0,"",MIN(F7,I7,L7)) -> 50 | O7: =IF(COUNT(F7,I7,L7)=0,"",AVERAGE(F7,I7,L7)) -> 102.72333 | P7: =IF(COUNT(F7,I7,L7)=0,"",MEDIAN(F7,I7,L7)) -> 96.5 | Q7: =IF(COUNT(F7,I7,L7)=0,"",MAX(F7,I7,L7)) -> 161.67 | R7: 250 | S7: =IF(ISNUMBER(R7),ROUNDDOWN(R7*0.96,2),"—") -> 240 | T7: =IF(COUNT(F7,I7,L7)=0,"Sem cotação",ROUND(P7,2)) -> 96.5 | U7: =IF(AND(ISNUMBER(R7),ISNUMBER(T7)),T7/R7-1,"—") -> -0.614 | V7: =IF(ISNUMBER(T7),D7*T7,0) -> 2095980
A8: 6 | B8: Consulta especializada na área de UROLOGIA, em unidade móvel temporária | C8: Consulta | D8: 14480 | E8: SESA/ES – Credenciamento SRSV/NRA 001/2026 (consulta médica especializada adulto) | F8: 50 | G8: https://saude.es.gov.br/Media/sesa/Credenciamento/EDITAL%20SESA-SRSV-NRA%20001-26.pdf | H8: CISAME/MG – Tabela de Preços e Serviços 2026 (Credenciamento 01/2025, Contrato 10/2026) | I8: 103.2 | J8: https://www.cisame.mg.gov.br/compliance/tabela-de-precos-e-servicos/ | K8: Pref. Três Lagoas/MS – Edital de Credenciamento 002/2026 (valor único para todas as especialidades) | L8: 115 | M8: https://www.treslagoas.ms.gov.br/prefeitura-de-tres-lagoas-amplia-acesso-a-consultas-especializadas-com-novo-credenciamento-na-saude/ | N8: =IF(COUNT(F8,I8,L8)=0,"",MIN(F8,I8,L8)) -> 50 | O8: =IF(COUNT(F8,I8,L8)=0,"",AVERAGE(F8,I8,L8)) -> 89.4 | P8: =IF(COUNT(F8,I8,L8)=0,"",MEDIAN(F8,I8,L8)) -> 103.2 | Q8: =IF(COUNT(F8,I8,L8)=0,"",MAX(F8,I8,L8)) -> 115 | R8: 250 | S8: =IF(ISNUMBER(R8),ROUNDDOWN(R8*0.96,2),"—") -> 240 | T8: =IF(COUNT(F8,I8,L8)=0,"Sem cotação",ROUND(P8,2)) -> 103.2 | U8: =IF(AND(ISNUMBER(R8),ISNUMBER(T8)),T8/R8-1,"—") -> -0.5872 | V8: =IF(ISNUMBER(T8),D8*T8,0) -> 1494336
A9: 7 | B9: Consulta especializada na área de REUMATOLOGIA, em unidade móvel temporária | C9: Consulta | D9: 13575 | E9: SESA/ES – Credenciamento SRSV/NRA 001/2026 (consulta médica especializada adulto) | F9: 50 | G9: https://saude.es.gov.br/Media/sesa/Credenciamento/EDITAL%20SESA-SRSV-NRA%20001-26.pdf | H9: CISAME/MG – Tabela de Preços e Serviços 2026 (Credenciamento 01/2025, Contrato 10/2026) | I9: 101.56 | J9: https://www.cisame.mg.gov.br/compliance/tabela-de-precos-e-servicos/ | K9: Pref. Três Lagoas/MS – Edital de Credenciamento 002/2026 (valor único para todas as especialidades) | L9: 115 | M9: https://www.treslagoas.ms.gov.br/prefeitura-de-tres-lagoas-amplia-acesso-a-consultas-especializadas-com-novo-credenciamento-na-saude/ | N9: =IF(COUNT(F9,I9,L9)=0,"",MIN(F9,I9,L9)) -> 50 | O9: =IF(COUNT(F9,I9,L9)=0,"",AVERAGE(F9,I9,L9)) -> 88.853333 | P9: =IF(COUNT(F9,I9,L9)=0,"",MEDIAN(F9,I9,L9)) -> 101.56 | Q9: =IF(COUNT(F9,I9,L9)=0,"",MAX(F9,I9,L9)) -> 115 | R9: 250 | S9: =IF(ISNUMBER(R9),ROUNDDOWN(R9*0.96,2),"—") -> 240 | T9: =IF(COUNT(F9,I9,L9)=0,"Sem cotação",ROUND(P9,2)) -> 101.56 | U9: =IF(AND(ISNUMBER(R9),ISNUMBER(T9)),T9/R9-1,"—") -> -0.59376 | V9: =IF(ISNUMBER(T9),D9*T9,0) -> 1378677
A10: 8 | B10: Consulta especializada na área de PNEUMOLOGIA, em unidade móvel temporária | C10: Consulta | D10: 12670 | E10: SESA/ES – Credenciamento SRSV/NRA 001/2026 (consulta médica especializada adulto) | F10: 50 | G10: https://saude.es.gov.br/Media/sesa/Credenciamento/EDITAL%20SESA-SRSV-NRA%20001-26.pdf | H10: CISAME/MG – Tabela de Preços e Serviços 2026 (Credenciamento 01/2025, Contrato 10/2026) | I10: 116.67 | J10: https://www.cisame.mg.gov.br/compliance/tabela-de-precos-e-servicos/ | K10: Pref. Três Lagoas/MS – Edital de Credenciamento 002/2026 (valor único para todas as especialidades) | L10: 115 | M10: https://www.treslagoas.ms.gov.br/prefeitura-de-tres-lagoas-amplia-acesso-a-consultas-especializadas-com-novo-credenciamento-na-saude/ | N10: =IF(COUNT(F10,I10,L10)=0,"",MIN(F10,I10,L10)) -> 50 | O10: =IF(COUNT(F10,I10,L10)=0,"",AVERAGE(F10,I10,L10)) -> 93.89 | P10: =IF(COUNT(F10,I10,L10)=0,"",MEDIAN(F10,I10,L10)) -> 115 | Q10: =IF(COUNT(F10,I10,L10)=0,"",MAX(F10,I10,L10)) -> 116.67 | R10: 250 | S10: =IF(ISNUMBER(R10),ROUNDDOWN(R10*0.96,2),"—") -> 240 | T10: =IF(COUNT(F10,I10,L10)=0,"Sem cotação",ROUND(P10,2)) -> 115 | U10: =IF(AND(ISNUMBER(R10),ISNUMBER(T10)),T10/R10-1,"—") -> -0.54 | V10: =IF(ISNUMBER(T10),D10*T10,0) -> 1457050
A11: 9 | B11: Consulta especializada na área de PROCTOLOGIA, em unidade móvel temporária | C11: Consulta | D11: 11765 | E11: SESA/ES – Credenciamento SRSV/NRA 001/2026 (consulta médica especializada adulto) | F11: 50 | G11: https://saude.es.gov.br/Media/sesa/Credenciamento/EDITAL%20SESA-SRSV-NRA%20001-26.pdf | H11: CISAME/MG – Tabela de Preços e Serviços 2026 (Credenciamento 01/2025, Contrato 10/2026) (consulta médica especializada (valor geral da tabela)) | I11: 90 | J11: https://www.cisame.mg.gov.br/compliance/tabela-de-precos-e-servicos/ | K11: Pref. Três Lagoas/MS – Edital de Credenciamento 002/2026 (valor único para todas as especialidades) | L11: 115 | M11: https://www.treslagoas.ms.gov.br/prefeitura-de-tres-lagoas-amplia-acesso-a-consultas-especializadas-com-novo-credenciamento-na-saude/ | N11: =IF(COUNT(F11,I11,L11)=0,"",MIN(F11,I11,L11)) -> 50 | O11: =IF(COUNT(F11,I11,L11)=0,"",AVERAGE(F11,I11,L11)) -> 85 | P11: =IF(COUNT(F11,I11,L11)=0,"",MEDIAN(F11,I11,L11)) -> 90 | Q11: =IF(COUNT(F11,I11,L11)=0,"",MAX(F11,I11,L11)) -> 115 | R11: 250 | S11: =IF(ISNUMBER(R11),ROUNDDOWN(R11*0.96,2),"—") -> 240 | T11: =IF(COUNT(F11,I11,L11)=0,"Sem cotação",ROUND(P11,2)) -> 90 | U11: =IF(AND(ISNUMBER(R11),ISNUMBER(T11)),T11/R11-1,"—") -> -0.64 | V11: =IF(ISNUMBER(T11),D11*T11,0) -> 1058850
A12: 10 | B12: Consulta especializada na área de NEFROLOGIA, em unidade móvel temporária | C12: Consulta | D12: 10860 | E12: SESA/ES – Credenciamento SRSV/NRA 001/2026 (consulta médica especializada adulto) | F12: 50 | G12: https://saude.es.gov.br/Media/sesa/Credenciamento/EDITAL%20SESA-SRSV-NRA%20001-26.pdf | H12: CISPARA/MG – Tabela Oficial de Consultas, Procedimentos e Serviços jan/2026 | I12: 105.87 | J12: https://www.cispara.mg.gov.br/transparencia/tabela-oficial-de-procedimentos/tabela-oficial-de-procedimentos-2026/543-01-tabela-oficial-de-consultas-procedimentos-e-servicos-janeiro-de-2026/file | K12: Pref. Três Lagoas/MS – Edital de Credenciamento 002/2026 (valor único para todas as especialidades) | L12: 115 | M12: https://www.treslagoas.ms.gov.br/prefeitura-de-tres-lagoas-amplia-acesso-a-consultas-especializadas-com-novo-credenciamento-na-saude/ | N12: =IF(COUNT(F12,I12,L12)=0,"",MIN(F12,I12,L12)) -> 50 | O12: =IF(COUNT(F12,I12,L12)=0,"",AVERAGE(F12,I12,L12)) -> 90.29 | P12: =IF(COUNT(F12,I12,L12)=0,"",MEDIAN(F12,I12,L12)) -> 105.87 | Q12: =IF(COUNT(F12,I12,L12)=0,"",MAX(F12,I12,L12)) -> 115 | R12: 250 | S12: =IF(ISNUMBER(R12),ROUNDDOWN(R12*0.96,2),"—") -> 240 | T12: =IF(COUNT(F12,I12,L12)=0,"Sem cotação",ROUND(P12,2)) -> 105.87 | U12: =IF(AND(ISNUMBER(R12),ISNUMBER(T12)),T12/R12-1,"—") -> -0.57652 | V12: =IF(ISNUMBER(T12),D12*T12,0) -> 1149748.2
A13: 11 | B13: Consulta especializada na área de ANGIOLOGIA, em unidade móvel temporária | C13: Consulta | D13: 9955 | E13: SESA/ES – Credenciamento SRSV/NRA 001/2026 (consulta médica especializada adulto) | F13: 50 | G13: https://saude.es.gov.br/Media/sesa/Credenciamento/EDITAL%20SESA-SRSV-NRA%20001-26.pdf | H13: CISAME/MG – Tabela de Preços e Serviços 2026 (Credenciamento 01/2025, Contrato 10/2026) | I13: 106.1 | J13: https://www.cisame.mg.gov.br/compliance/tabela-de-precos-e-servicos/ | K13: Pref. Três Lagoas/MS – Edital de Credenciamento 002/2026 (valor único para todas as especialidades) | L13: 115 | M13: https://www.treslagoas.ms.gov.br/prefeitura-de-tres-lagoas-amplia-acesso-a-consultas-especializadas-com-novo-credenciamento-na-saude/ | N13: =IF(COUNT(F13,I13,L13)=0,"",MIN(F13,I13,L13)) -> 50 | O13: =IF(COUNT(F13,I13,L13)=0,"",AVERAGE(F13,I13,L13)) -> 90.366667 | P13: =IF(COUNT(F13,I13,L13)=0,"",MEDIAN(F13,I13,L13)) -> 106.1 | Q13: =IF(COUNT(F13,I13,L13)=0,"",MAX(F13,I13,L13)) -> 115 | R13: 250 | S13: =IF(ISNUMBER(R13),ROUNDDOWN(R13*0.96,2),"—") -> 240 | T13: =IF(COUNT(F13,I13,L13)=0,"Sem cotação",ROUND(P13,2)) -> 106.1 | U13: =IF(AND(ISNUMBER(R13),ISNUMBER(T13)),T13/R13-1,"—") -> -0.5756 | V13: =IF(ISNUMBER(T13),D13*T13,0) -> 1056225.5
A14: 12 | B14: Consulta especializada na área de GERIATRIA, em unidade móvel temporária | C14: Consulta | D14: 3620 | E14: SESA/ES – Credenciamento SRSV/NRA 001/2026 (consulta médica especializada adulto) | F14: 50 | G14: https://saude.es.gov.br/Media/sesa/Credenciamento/EDITAL%20SESA-SRSV-NRA%20001-26.pdf | H14: CISAME/MG – Tabela de Preços e Serviços 2026 (Credenciamento 01/2025, Contrato 10/2026) | I14: 97.63 | J14: https://www.cisame.mg.gov.br/compliance/tabela-de-precos-e-servicos/ | K14: Pref. Três Lagoas/MS – Edital de Credenciamento 002/2026 (valor único para todas as especialidades) | L14: 115 | M14: https://www.treslagoas.ms.gov.br/prefeitura-de-tres-lagoas-amplia-acesso-a-consultas-especializadas-com-novo-credenciamento-na-saude/ | N14: =IF(COUNT(F14,I14,L14)=0,"",MIN(F14,I14,L14)) -> 50 | O14: =IF(COUNT(F14,I14,L14)=0,"",AVERAGE(F14,I14,L14)) -> 87.543333 | P14: =IF(COUNT(F14,I14,L14)=0,"",MEDIAN(F14,I14,L14)) -> 97.63 | Q14: =IF(COUNT(F14,I14,L14)=0,"",MAX(F14,I14,L14)) -> 115 | R14: 250 | S14: =IF(ISNUMBER(R14),ROUNDDOWN(R14*0.96,2),"—") -> 240 | T14: =IF(COUNT(F14,I14,L14)=0,"Sem cotação",ROUND(P14,2)) -> 97.63 | U14: =IF(AND(ISNUMBER(R14),ISNUMBER(T14)),T14/R14-1,"—") -> -0.60948 | V14: =IF(ISNUMBER(T14),D14*T14,0) -> 353420.6
... A17: 15 | B17: Consulta especializada na área de CARDIOLOGIA, em unidade móvel temporária | C17: Consulta | D17: 2172 | E17: SESA/ES – Credenciamento SRSV/NRA 001/2026 (consulta médica especializada adulto) | F17: 50 | G17: https://saude.es.gov.br/Media/sesa/Credenciamento/EDITAL%20SESA-SRSV-NRA%20001-26.pdf | H17: CISAME/MG – Tabela de Preços e Serviços 2026 (Credenciamento 01/2025, Contrato 10/2026) | I17: 95.2 | J17: https://www.cisame.mg.gov.br/compliance/tabela-de-precos-e-servicos/ | K17: Pref. Iuiú/BA – Edital de Credenciamento 022/2026 | L17: 161.67 | M17: https://www.procede.api.br/publica/documentos/PRYXAMTCDSCNU-20260528-145706--!--CREDENCIAMENTO_MEDICOS_EDITAL_2026.pdf | N17: =IF(COUNT(F17,I17,L17)=0,"",MIN(F17,I17,L17)) -> 50 | O17: =IF(COUNT(F17,I17,L17)=0,"",AVERAGE(F17,I17,L17)) -> 102.29 | P17: =IF(COUNT(F17,I17,L17)=0,"",MEDIAN(F17,I17,L17)) -> 95.2 | Q17: =IF(COUNT(F17,I17,L17)=0,"",MAX(F17,I17,L17)) -> 161.67 | R17: 250 | S17: =IF(ISNUMBER(R17),ROUNDDOWN(R17*0.96,2),"—") -> 240 | T17: =IF(COUNT(F17,I17,L17)=0,"Sem cotação",ROUND(P17,2)) -> 95.2 | U17: =IF(AND(ISNUMBER(R17),ISNUMBER(T17)),T17/R17-1,"—") -> -0.6192 | V17: =IF(ISNUMBER(T17),D17*T17,0) -> 206774.4
B18: SUBTOTAL DO LOTE | V18: =SUM(V3:V17) -> 22868454

Sheet Lote 3 - Exames
A1: LOTE 3 – EXAMES DIAGNÓSTICOS (unidade móvel)
A2: Item | B2: Descrição | C2: Unid. | D2: Qtd. estimada | E2: Fonte 1 | F2: Valor 1 (R$) | G2: Link 1 | H2: Fonte 2 | I2: Valor 2 (R$) | J2: Link 2 | K2: Fonte 3 | L2: Valor 3 (R$) | M2: Link 3 | N2: Menor (R$) | O2: Média (R$) | P2: Mediana (R$) | Q2: Maior (R$) | R2: Valor ICISMEP – TSPS 2026, serviço em unidade móvel/itinerante (R$) | S2: Teto de verificação: ICISMEP − 4% (R$) | T2: Valor unit. referência (R$) | U2: Diferença ref. x ICISMEP (%) | V2: Valor total estimado (R$)
A3: 1 | B3: ULTRASSONOGRAFIA DE ABDOME TOTAL, em unidade móvel, com laudo | C3: Exame | D3: 65600 | E3: Pref. Sarapuí/SP – Ata de Registro de Preços (RM e USG) | F3: 115.05 | G3: https://www.sarapui.sp.gov.br/ata-registro-preco/page/1/download/839 | H3: CISPARA/MG – Tabela Oficial de Consultas, Procedimentos e Serviços jan/2026 | I3: 83.54 | J3: https://www.cispara.mg.gov.br/transparencia/tabela-oficial-de-procedimentos/tabela-oficial-de-procedimentos-2026/543-01-tabela-oficial-de-consultas-procedimentos-e-servicos-janeiro-de-2026/file | K3: CIM Expandida Sul – Tabela de valores vigente a partir de 01/01/2026 | L3: 60.72 | M3: https://www.cimexpandidasul.com.br/institucional/tabela-de-servicos/562-tabela-atualizada-01-01-2026/file | N3: =IF(COUNT(F3,I3,L3)=0,"",MIN(F3,I3,L3)) -> 60.72 | O3: =IF(COUNT(F3,I3,L3)=0,"",AVERAGE(F3,I3,L3)) -> 86.436667 | P3: =IF(COUNT(F3,I3,L3)=0,"",MEDIAN(F3,I3,L3)) -> 83.54 | Q3: =IF(COUNT(F3,I3,L3)=0,"",MAX(F3,I3,L3)) -> 115.05 | R3: 87.92 | S3: =IF(ISNUMBER(R3),ROUNDDOWN(R3*0.96,2),"—") -> 84.4 | T3: =IF(COUNT(F3,I3,L3)=0,"Sem cotação",ROUND(P3,2)) -> 83.54 | U3: =IF(AND(ISNUMBER(R3),ISNUMBER(T3)),T3/R3-1,"—") -> -0.049818016 | V3: =IF(ISNUMBER(T3),D3*T3,0) -> 5480224
A4: 2 | B4: ULTRASSONOGRAFIA TRANSVAGINAL (ENDOVAGINAL), em unidade móvel, com laudo | C4: Exame | D4: 10460 | E4: FMS Quilombo/SC – Credenciamento 05/2025 | F4: 90 | G4: https://quilombo.sc.gov.br/uploads/sites/96/2025/04/5-EDITAL-DE-CREDENCIAMENTO-05-2025-exames-imagem.pdf | H4: CISPARA/MG – Tabela Oficial de Consultas, Procedimentos e Serviços jan/2026 | I4: 77.4 | J4: https://www.cispara.mg.gov.br/transparencia/tabela-oficial-de-procedimentos/tabela-oficial-de-procedimentos-2026/543-01-tabela-oficial-de-consultas-procedimentos-e-servicos-janeiro-de-2026/file | K4: CISAMUSEP/PR – Tabela CISAMUSEP 2026 | L4: 53.07 | M4: https://www.cisamusep.org.br/uploads/arquivoChamamento/TABELA-CISAMUSEP-2026.pdf | N4: =IF(COUNT(F4,I4,L4)=0,"",MIN(F4,I4,L4)) -> 53.07 | O4: =IF(COUNT(F4,I4,L4)=0,"",AVERAGE(F4,I4,L4)) -> 73.49 | P4: =IF(COUNT(F4,I4,L4)=0,"",MEDIAN(F4,I4,L4)) -> 77.4 | Q4: =IF(COUNT(F4,I4,L4)=0,"",MAX(F4,I4,L4)) -> 90 | R4: 87.92 | S4: =IF(ISNUMBER(R4),ROUNDDOWN(R4*0.96,2),"—") -> 84.4 | T4: =IF(COUNT(F4,I4,L4)=0,"Sem cotação",ROUND(P4,2)) -> 77.4 | U4: =IF(AND(ISNUMBER(R4),ISNUMBER(T4)),T4/R4-1,"—") -> -0.11965423 | V4: =IF(ISNUMBER(T4),D4*T4,0) -> 809604
A5: 3 | B5: ULTRASSONOGRAFIA DE VIAS URINÁRIAS, em unidade móvel, com laudo | C5: Exame | D5: 21325 | E5: Pref. Sarapuí/SP – Ata de Registro de Preços (RM e USG) | F5: 62.79 | G5: https://www.sarapui.sp.gov.br/ata-registro-preco/page/1/download/839 | H5: CISPARA/MG – Tabela Oficial de Consultas, Procedimentos e Serviços jan/2026 (aparelho urinário) | I5: 81.87 | J5: https://www.cispara.mg.gov.br/transparencia/tabela-oficial-de-procedimentos/tabela-oficial-de-procedimentos-2026/543-01-tabela-oficial-de-consultas-procedimentos-e-servicos-janeiro-de-2026/file | K5: Pref. Lucas do Rio Verde/MT – Credenciamento 002/2026 (Inexig. 006/2026) (aparelho urinário) | L5: 89.72 | M5: https://lucasdorioverde.mt.gov.br/arquivos//licitacoes/3709/edital.pdf | N5: =IF(COUNT(F5,I5,L5)=0,"",MIN(F5,I5,L5)) -> 62.79 | O5: =IF(COUNT(F5,I5,L5)=0,"",AVERAGE(F5,I5,L5)) -> 78.126667 | P5: =IF(COUNT(F5,I5,L5)=0,"",MEDIAN(F5,I5,L5)) -> 81.87 | Q5: =IF(COUNT(F5,I5,L5)=0,"",MAX(F5,I5,L5)) -> 89.72 | R5: 87.92 | S5: =IF(ISNUMBER(R5),ROUNDDOWN(R5*0.96,2),"—") -> 84.4 | T5: =IF(COUNT(F5,I5,L5)=0,"Sem cotação",ROUND(P5,2)) -> 81.87 | U5: =IF(AND(ISNUMBER(R5),ISNUMBER(T5)),T5/R5-1,"—") -> -0.068812557 | V5: =IF(ISNUMBER(T5),D5*T5,0) -> 1745877.8
A6: 4 | B6: ULTRASSONOGRAFIA DE PRÓSTATA (VIA ABDOMINAL), em unidade móvel, com laudo | C6: Exame | D6: 10460 | E6: FMS Quilombo/SC – Credenciamento 05/2025 | F6: 90 | G6: https://quilombo.sc.gov.br/uploads/sites/96/2025/04/5-EDITAL-DE-CREDENCIAMENTO-05-2025-exames-imagem.pdf | H6: CISPARA/MG – Tabela Oficial de Consultas, Procedimentos e Serviços jan/2026 | I6: 71.28 | J6: https://www.cispara.mg.gov.br/transparencia/tabela-oficial-de-procedimentos/tabela-oficial-de-procedimentos-2026/543-01-tabela-oficial-de-consultas-procedimentos-e-servicos-janeiro-de-2026/file | K6: CIM Expandida Sul – Tabela de valores vigente a partir de 01/01/2026 | L6: 44.28 | M6: https://www.cimexpandidasul.com.br/institucional/tabela-de-servicos/562-tabela-atualizada-01-01-2026/file | N6: =IF(COUNT(F6,I6,L6)=0,"",MIN(F6,I6,L6)) -> 44.28 | O6: =IF(COUNT(F6,I6,L6)=0,"",AVERAGE(F6,I6,L6)) -> 68.52 | P6: =IF(COUNT(F6,I6,L6)=0,"",MEDIAN(F6,I6,L6)) -> 71.28 | Q6: =IF(COUNT(F6,I6,L6)=0,"",MAX(F6,I6,L6)) -> 90 | R6: 87.92 | S6: =IF(ISNUMBER(R6),ROUNDDOWN(R6*0.96,2),"—") -> 84.4 | T6: =IF(COUNT(F6,I6,L6)=0,"Sem cotação",ROUND(P6,2)) -> 71.28 | U6: =IF(AND(ISNUMBER(R6),ISNUMBER(T6)),T6/R6-1,"—") -> -0.18926297 | V6: =IF(ISNUMBER(T6),D6*T6,0) -> 745588.8
A7: 5 | B7: ECOCARDIOGRAMA TRANSTORÁCICO, em unidade móvel, com laudo | C7: Exame | D7: 14885 | E7: Fundação iNOVA Capixaba/ES – Pregão Eletrônico 068/2025 | F7: 211.26 | G7: https://inovacapixaba.es.gov.br/media/Editais/Licita%C3%A7%C3%A3o/Preg%C3%A3o/Edital_n%C2%BA_068_2025_2024_T5Q1Z_Servi%C3%A7os_M%C3%A9dicos_de_Ecocardiograma_REPUBL..pdf | H7: Pref. Paragominas/PA – Pregão Eletrônico 9/2026-000027 (ecocardiograma transtorácico com doppler) | I7: 244.92 | J7: https://pncp.gov.br/app/editais/05193057000178/2026/124 | K7: CISAME/MG – Tabela de Preços e Serviços 2026 (Credenciamento 01/2025, Contrato 10/2026) | L7: 190.45 | M7: https://www.cisame.mg.gov.br/compliance/tabela-de-precos-e-servicos/ | N7: =IF(COUNT(F7,I7,L7)=0,"",MIN(F7,I7,L7)) -> 190.45 | O7: =IF(COUNT(F7,I7,L7)=0,"",AVERAGE(F7,I7,L7)) -> 215.54333 | P7: =IF(COUNT(F7,I7,L7)=0,"",MEDIAN(F7,I7,L7)) -> 211.26 | Q7: =IF(COUNT(F7,I7,L7)=0,"",MAX(F7,I7,L7)) -> 244.92 | R7: Sem correspondente | S7: =IF(ISNUMBER(R7),ROUNDDOWN(R7*0.96,2),"—") -> — | T7: =IF(COUNT(F7,I7,L7)=0,"Sem cotação",ROUND(P7,2)) -> 211.26 | U7: =IF(AND(ISNUMBER(R7),ISNUMBER(T7)),T7/R7-1,"—") -> — | V7: =IF(ISNUMBER(T7),D7*T7,0) -> 3144605.1
A8: 6 | B8: DENSITOMETRIA ÓSSEA, em unidade móvel, com laudo | C8: Exame | D8: 3174 | E8: Pref. Foz do Jordão/PR – Credenciamento 008/2025 (corpo inteiro) | F8: 187.17 | G8: https://pncp.gov.br/pncp-api/v1/orgaos/01603719000180/compras/2025/95/arquivos/1 | H8: CIM Expandida Sul – Tabela de valores vigente a partir de 01/01/2026 | I8: 64.37 | J8: https://www.cimexpandidasul.com.br/institucional/tabela-de-servicos/562-tabela-atualizada-01-01-2026/file | K8: Pref. Praia Grande/SP – Tabela Oficial de Valores SESAP 2026 (coluna e/ou fêmur) | L8: 75 | M8: https://www.praiagrande.sp.gov.br/arquivos/ChamadaPublica/46047.pdf | N8: =IF(COUNT(F8,I8,L8)=0,"",MIN(F8,I8,L8)) -> 64.37 | O8: =IF(COUNT(F8,I8,L8)=0,"",AVERAGE(F8,I8,L8)) -> 108.84667 | P8: =IF(COUNT(F8,I8,L8)=0,"",MEDIAN(F8,I8,L8)) -> 75 | Q8: =IF(COUNT(F8,I8,L8)=0,"",MAX(F8,I8,L8)) -> 187.17 | R8: Sem correspondente | S8: =IF(ISNUMBER(R8),ROUNDDOWN(R8*0.96,2),"—") -> — | T8: =IF(COUNT(F8,I8,L8)=0,"Sem cotação",ROUND(P8,2)) -> 75 | U8: =IF(AND(ISNUMBER(R8),ISNUMBER(T8)),T8/R8-1,"—") -> — | V8: =IF(ISNUMBER(T8),D8*T8,0) -> 238050
A9: 7 | B9: ULTRASSONOGRAFIA DE MAMAS, em unidade móvel, com laudo | C9: Exame | D9: 4525 | E9: FMS Quilombo/SC – Credenciamento 05/2025 | F9: 90 | G9: https://quilombo.sc.gov.br/uploads/sites/96/2025/04/5-EDITAL-DE-CREDENCIAMENTO-05-2025-exames-imagem.pdf | H9: COPIRN – Tabela de Serviços de Saúde (publ. 01/2025) (mamária bilateral) | I9: 76.88 | J9: https://copirn.org.br/wp-content/uploads/2025/01/TABELA-DE-SERVICOS-DE-SAUDE-COPIRN-2.pdf | K9: CISAMUSEP/PR – Tabela CISAMUSEP 2026 (mamária bilateral) | L9: 47.76 | M9: https://www.cisamusep.org.br/uploads/arquivoChamamento/TABELA-CISAMUSEP-2026.pdf | N9: =IF(COUNT(F9,I9,L9)=0,"",MIN(F9,I9,L9)) -> 47.76 | O9: =IF(COUNT(F9,I9,L9)=0,"",AVERAGE(F9,I9,L9)) -> 71.546667 | P9: =IF(COUNT(F9,I9,L9)=0,"",MEDIAN(F9,I9,L9)) -> 76.88 | Q9: =IF(COUNT(F9,I9,L9)=0,"",MAX(F9,I9,L9)) -> 90 | R9: 87.92 | S9: =IF(ISNUMBER(R9),ROUNDDOWN(R9*0.96,2),"—") -> 84.4 | T9: =IF(COUNT(F9,I9,L9)=0,"Sem cotação",ROUND(P9,2)) -> 76.88 | U9: =IF(AND(ISNUMBER(R9),ISNUMBER(T9)),T9/R9-1,"—") -> -0.1255687 | V9: =IF(ISNUMBER(T9),D9*T9,0) -> 347882
A10: 8 | B10: ULTRASSONOGRAFIA DE AXILAS, em unidade móvel, com laudo | C10: Exame | D10: 4525 | E10: FMS Vargem/SC – Pregão Eletrônico 005/2025 (análogo: partes moles) | F10: 100.74 | G10: https://www.vargem.sc.gov.br/uploads/sites/94/2025/03/Edital-FMS-VRG-2025_013_PE_005_90023-Ultrassom.pdf | H10: COPIRN – Tabela de Serviços de Saúde (publ. 01/2025) (análogo: mamária bilateral) | I10: 76.88 | J10: https://copirn.org.br/wp-content/uploads/2025/01/TABELA-DE-SERVICOS-DE-SAUDE-COPIRN-2.pdf | K10: CISAMUSEP/PR – Tabela CISAMUSEP 2026 (análogo: mamária bilateral) | L10: 47.76 | M10: https://www.cisamusep.org.br/uploads/arquivoChamamento/TABELA-CISAMUSEP-2026.pdf | N10: =IF(COUNT(F10,I10,L10)=0,"",MIN(F10,I10,L10)) -> 47.76 | O10: =IF(COUNT(F10,I10,L10)=0,"",AVERAGE(F10,I10,L10)) -> 75.126667 | P10: =IF(COUNT(F10,I10,L10)=0,"",MEDIAN(F10,I10,L10)) -> 76.88 | Q10: =IF(COUNT(F10,I10,L10)=0,"",MAX(F10,I10,L10)) -> 100.74 | R10: 87.92 | S10: =IF(ISNUMBER(R10),ROUNDDOWN(R10*0.96,2),"—") -> 84.4 | T10: =IF(COUNT(F10,I10,L10)=0,"Sem cotação",ROUND(P10,2)) -> 76.88 | U10: =IF(AND(ISNUMBER(R10),ISNUMBER(T10)),T10/R10-1,"—") -> -0.1255687 | V10: =IF(ISNUMBER(T10),D10*T10,0) -> 347882
A11: 9 | B11: ULTRASSONOGRAFIA DE ARTICULAÇÕES/PARTES MOLES, em unidade móvel, com laudo | C11: Exame | D11: 54300 | E11: FMS Quilombo/SC – Credenciamento 05/2025 | F11: 95.31 | G11: https://quilombo.sc.gov.br/uploads/sites/96/2025/04/5-EDITAL-DE-CREDENCIAMENTO-05-2025-exames-imagem.pdf | H11: CISUM/MG – Credenciamento 2026 (ultrassonografias, sob demanda) (musculoesquelética/articulação) | I11: 80 | J11: https://ia.mabus.com.br/licitacao/6466406/credenciamento-consorcio-intermunicipal-de-saude-uniao-da-mata-leopoldina-mg | K11: CIM Expandida Sul – Tabela de valores vigente a partir de 01/01/2026 | L11: 54.87 | M11: https://www.cimexpandidasul.com.br/institucional/tabela-de-servicos/562-tabela-atualizada-01-01-2026/file | N11: =IF(COUNT(F11,I11,L11)=0,"",MIN(F11,I11,L11)) -> 54.87 | O11: =IF(COUNT(F11,I11,L11)=0,"",AVERAGE(F11,I11,L11)) -> 76.726667 | P11: =IF(COUNT(F11,I11,L11)=0,"",MEDIAN(F11,I11,L11)) -> 80 | Q11: =IF(COUNT(F11,I11,L11)=0,"",MAX(F11,I11,L11)) -> 95.31 | R11: 87.92 | S11: =IF(ISNUMBER(R11),ROUNDDOWN(R11*0.96,2),"—") -> 84.4 | T11: =IF(COUNT(F11,I11,L11)=0,"Sem cotação",ROUND(P11,2)) -> 80 | U11: =IF(AND(ISNUMBER(R11),ISNUMBER(T11)),T11/R11-1,"—") -> -0.090081893 | V11: =IF(ISNUMBER(T11),D11*T11,0) -> 4344000
B12: SUBTOTAL DO LOTE | V12: =SUM(V3:V11) -> 17203714

Sheet Lote 4 - Ressonancia
A1: LOTE 4 – RESSONÂNCIA MAGNÉTICA (unidade móvel)
A2: Item | B2: Descrição | C2: Unid. | D2: Qtd. estimada | E2: Fonte 1 | F2: Valor 1 (R$) | G2: Link 1 | H2: Fonte 2 | I2: Valor 2 (R$) | J2: Link 2 | K2: Fonte 3 | L2: Valor 3 (R$) | M2: Link 3 | N2: Menor (R$) | O2: Média (R$) | P2: Mediana (R$) | Q2: Maior (R$) | R2: Valor ICISMEP – TSPS 2026, serviço em unidade móvel/itinerante (R$) | S2: Teto de verificação: ICISMEP − 4% (R$) | T2: Valor unit. referência (R$) | U2: Diferença ref. x ICISMEP (%) | V2: Valor total estimado (R$)
A3: 1 | B3: RESSONÂNCIA MAGNÉTICA, em unidade móvel, valor único por exame independentemente da região anatômica | C3: Exame | D3: 27150 | E3: CIS Circuito das Águas/MG – Credenciamento 04/2025 (Proc. 054/2025), carreta itinerante (carreta itinerante) | F3: 420 | G3: https://pncp.gov.br/pncp-api/v1/orgaos/71203715000190/compras/2026/1/arquivos/1 | H3: Pref. Livramento de Nossa Senhora/BA – Chamamento Público 008/2026 (sem contraste) | I3: 400 | J3: https://pncp.gov.br/app/editais/13674817000197/2026/64 | K3: Pref. Iuiú/BA – Edital de Credenciamento 022/2026 (sem contraste) | L3: 543.33 | M3: https://www.procede.api.br/publica/documentos/PRYXAMTCDSCNU-20260528-145706--!--CREDENCIAMENTO_MEDICOS_EDITAL_2026.pdf | N3: =IF(COUNT(F3,I3,L3)=0,"",MIN(F3,I3,L3)) -> 400 | O3: =IF(COUNT(F3,I3,L3)=0,"",AVERAGE(F3,I3,L3)) -> 454.44333 | P3: =IF(COUNT(F3,I3,L3)=0,"",MEDIAN(F3,I3,L3)) -> 420 | Q3: =IF(COUNT(F3,I3,L3)=0,"",MAX(F3,I3,L3)) -> 543.33 | R3: Sem correspondente | S3: =IF(ISNUMBER(R3),ROUNDDOWN(R3*0.96,2),"—") -> — | T3: =IF(COUNT(F3,I3,L3)=0,"Sem cotação",ROUND(P3,2)) -> 420 | U3: =IF(AND(ISNUMBER(R3),ISNUMBER(T3)),T3/R3-1,"—") -> — | V3: =IF(ISNUMBER(T3),D3*T3,0) -> 11403000
A4: 2 | B4: CONTRASTE PARA RESSONÂNCIA MAGNÉTICA (meio de contraste, insumos e aplicação), vinculado ao item 1 | C4: Aplicação | D4: 4073 | E4: Pref. Sarapuí/SP – Ata de Registro de Preços (RM e USG) (diferença entre exame com e sem contraste) | F4: 77 | G4: https://www.sarapui.sp.gov.br/ata-registro-preco/page/1/download/839 | H4: Pref. Livramento de Nossa Senhora/BA – Chamamento Público 008/2026 (diferença: R$ 700,00 com contraste − R$ 400,00 sem) | I4: 300 | J4: https://pncp.gov.br/app/editais/13674817000197/2026/64 | K4: Pref. Iuiú/BA – Edital de Credenciamento 022/2026 (diferença: R$ 653,33 com contraste − R$ 543,33 sem) | L4: 110 | M4: https://www.procede.api.br/publica/documentos/PRYXAMTCDSCNU-20260528-145706--!--CREDENCIAMENTO_MEDICOS_EDITAL_2026.pdf | N4: =IF(COUNT(F4,I4,L4)=0,"",MIN(F4,I4,L4)) -> 77 | O4: =IF(COUNT(F4,I4,L4)=0,"",AVERAGE(F4,I4,L4)) -> 162.33333 | P4: =IF(COUNT(F4,I4,L4)=0,"",MEDIAN(F4,I4,L4)) -> 110 | Q4: =IF(COUNT(F4,I4,L4)=0,"",MAX(F4,I4,L4)) -> 300 | R4: Sem correspondente | S4: =IF(ISNUMBER(R4),ROUNDDOWN(R4*0.96,2),"—") -> — | T4: =IF(COUNT(F4,I4,L4)=0,"Sem cotação",ROUND(P4,2)) -> 110 | U4: =IF(AND(ISNUMBER(R4),ISNUMBER(T4)),T4/R4-1,"—") -> — | V4: =IF(ISNUMBER(T4),D4*T4,0) -> 448030
B5: SUBTOTAL DO LOTE | V5: =SUM(V3:V4) -> 11851030

Sheet Lote 5 - Odontologia
A1: LOTE 5 – ATENDIMENTOS E PROCEDIMENTOS ODONTOLÓGICOS (unidade móvel)
A2: Item | B2: Descrição | C2: Unid. | D2: Qtd. estimada | E2: Fonte 1 | F2: Valor 1 (R$) | G2: Link 1 | H2: Fonte 2 | I2: Valor 2 (R$) | J2: Link 2 | K2: Fonte 3 | L2: Valor 3 (R$) | M2: Link 3 | N2: Menor (R$) | O2: Média (R$) | P2: Mediana (R$) | Q2: Maior (R$) | R2: Valor ICISMEP – TSPS 2026, serviço em unidade móvel/itinerante (R$) | S2: Teto de verificação: ICISMEP − 4% (R$) | T2: Valor unit. referência (R$) | U2: Diferença ref. x ICISMEP (%) | V2: Valor total estimado (R$)
A3: 1 | B3: Consulta especializada em ODONTOLOGIA/SAÚDE BUCAL, em unidade móvel | C3: Consulta | D3: 90118 | E3: CIMINAS/MG – Termo de Contrato 741/2025 (Credenciamento 040/2025 – Sistema Carretas da Saúde), 30/09/2025 | F3: 66.5 | G3: https://ciminas.mg.gov.br | H3: Senado Federal/SIS – Tabela própria de credenciamento – Odontologia | I3: 90.1 | J3: https://www12.senado.leg.br/institucional/sis/pdfs/tabela-odontologia-v2-nv.pdf | K3: MPU/Plan-Assiste – Anexo V da Norma Complementar 50 (2026) | L3: 78.4 | M3: https://planassiste.mpu.mp.br/o-plan-assiste/normas/normas-cpmplementares/anexo_v_nc_50.pdf/@@download/file/Anexo_V_NC_50.pdf | N3: =IF(COUNT(F3,I3,L3)=0,"",MIN(F3,I3,L3)) -> 66.5 | O3: =IF(COUNT(F3,I3,L3)=0,"",AVERAGE(F3,I3,L3)) -> 78.333333 | P3: =IF(COUNT(F3,I3,L3)=0,"",MEDIAN(F3,I3,L3)) -> 78.4 | Q3: =IF(COUNT(F3,I3,L3)=0,"",MAX(F3,I3,L3)) -> 90.1 | R3: Sem correspondente | S3: =IF(ISNUMBER(R3),ROUNDDOWN(R3*0.96,2),"—") -> — | T3: =IF(COUNT(F3,I3,L3)=0,"Sem cotação",ROUND(P3,2)) -> 78.4 | U3: =IF(AND(ISNUMBER(R3),ISNUMBER(T3)),T3/R3-1,"—") -> — | V3: =IF(ISNUMBER(T3),D3*T3,0) -> 7065251.2
A4: 2 | B4: Atividade educativa em saúde bucal | C4: Procedimento | D4: 905 | E4: CIMINAS/MG – Termo de Contrato 741/2025 (Credenciamento 040/2025 – Sistema Carretas da Saúde), 30/09/2025 | F4: 53.8 | G4: https://ciminas.mg.gov.br | H4: Senado Federal/SIS – Tabela própria de credenciamento – Odontologia | I4: 76.05 | J4: https://www12.senado.leg.br/institucional/sis/pdfs/tabela-odontologia-v2-nv.pdf | K4: NUCLEP/MME – Tabela de Procedimentos Odontológicos | L4: 19 | M4: https://www.gov.br/mme/pt-br/assuntos/orgaos-vinculados/nuclep/plano-de-saude/orientacoes-ao-credenciado/TABELADEPROCEDIMENTOSODONTOLGICOS.pdf | N4: =IF(COUNT(F4,I4,L4)=0,"",MIN(F4,I4,L4)) -> 19 | O4: =IF(COUNT(F4,I4,L4)=0,"",AVERAGE(F4,I4,L4)) -> 49.616667 | P4: =IF(COUNT(F4,I4,L4)=0,"",MEDIAN(F4,I4,L4)) -> 53.8 | Q4: =IF(COUNT(F4,I4,L4)=0,"",MAX(F4,I4,L4)) -> 76.05 | R4: Sem correspondente | S4: =IF(ISNUMBER(R4),ROUNDDOWN(R4*0.96,2),"—") -> — | T4: =IF(COUNT(F4,I4,L4)=0,"Sem cotação",ROUND(P4,2)) -> 53.8 | U4: =IF(AND(ISNUMBER(R4),ISNUMBER(T4)),T4/R4-1,"—") -> — | V4: =IF(ISNUMBER(T4),D4*T4,0) -> 48689
A5: 3 | B5: Atividade educativa para pais e cuidadores | C5: Procedimento | D5: 905 | E5: CIMINAS/MG – Termo de Contrato 741/2025 (Credenciamento 040/2025 – Sistema Carretas da Saúde), 30/09/2025 (orientação de higiene bucal para pais/cuidadores) | F5: 53.8 | G5: https://ciminas.mg.gov.br | H5: Senado Federal/SIS – Tabela própria de credenciamento – Odontologia | I5: 76.05 | J5: https://www12.senado.leg.br/institucional/sis/pdfs/tabela-odontologia-v2-nv.pdf | K5: NUCLEP/MME – Tabela de Procedimentos Odontológicos (análogo) | L5: 19 | M5: https://www.gov.br/mme/pt-br/assuntos/orgaos-vinculados/nuclep/plano-de-saude/orientacoes-ao-credenciado/TABELADEPROCEDIMENTOSODONTOLGICOS.pdf | N5: =IF(COUNT(F5,I5,L5)=0,"",MIN(F5,I5,L5)) -> 19 | O5: =IF(COUNT(F5,I5,L5)=0,"",AVERAGE(F5,I5,L5)) -> 49.616667 | P5: =IF(COUNT(F5,I5,L5)=0,"",MEDIAN(F5,I5,L5)) -> 53.8 | Q5: =IF(COUNT(F5,I5,L5)=0,"",MAX(F5,I5,L5)) -> 76.05 | R5: Sem correspondente | S5: =IF(ISNUMBER(R5),ROUNDDOWN(R5*0.96,2),"—") -> — | T5: =IF(COUNT(F5,I5,L5)=0,"Sem cotação",ROUND(P5,2)) -> 53.8 | U5: =IF(AND(ISNUMBER(R5),ISNUMBER(T5)),T5/R5-1,"—") -> — | V5: =IF(ISNUMBER(T5),D5*T5,0) -> 48689
A6: 4 | B6: Adequação do meio bucal (por arcada) | C6: Procedimento | D6: 905 | E6: CIMINAS/MG – Termo de Contrato 741/2025 (Credenciamento 040/2025 – Sistema Carretas da Saúde), 30/09/2025 | F6: 69.5 | G6: https://ciminas.mg.gov.br | H6: Senado Federal/SIS – Tabela própria de credenciamento – Odontologia | I6: 98.27 | J6: https://www12.senado.leg.br/institucional/sis/pdfs/tabela-odontologia-v2-nv.pdf | K6: BC Saúde – Tabela de Reembolso Odontológico 2026 | L6: 83.97 | M6: https://www.bcb.gov.br/content/acessoinformacao/bcsaude_docs/Tabela_de_Reembolsos_procedimentos_odontologicos_2026.pdf | N6: =IF(COUNT(F6,I6,L6)=0,"",MIN(F6,I6,L6)) -> 69.5 | O6: =IF(COUNT(F6,I6,L6)=0,"",AVERAGE(F6,I6,L6)) -> 83.913333 | P6: =IF(COUNT(F6,I6,L6)=0,"",MEDIAN(F6,I6,L6)) -> 83.97 | Q6: =IF(COUNT(F6,I6,L6)=0,"",MAX(F6,I6,L6)) -> 98.27 | R6: Sem correspondente | S6: =IF(ISNUMBER(R6),ROUNDDOWN(R6*0.96,2),"—") -> — | T6: =IF(COUNT(F6,I6,L6)=0,"Sem cotação",ROUND(P6,2)) -> 83.97 | U6: =IF(AND(ISNUMBER(R6),ISNUMBER(T6)),T6/R6-1,"—") -> — | V6: =IF(ISNUMBER(T6),D6*T6,0) -> 75992.85
A7: 5 | B7: Ajuste oclusal por desgaste seletivo (por sessão) | C7: Procedimento | D7: 1376 | E7: CIMINAS/MG – Termo de Contrato 741/2025 (Credenciamento 040/2025 – Sistema Carretas da Saúde), 30/09/2025 | F7: 82.2 | G7: https://ciminas.mg.gov.br | H7: Senado Federal/SIS – Tabela própria de credenciamento – Odontologia | I7: 116.21 | J7: https://www12.senado.leg.br/institucional/sis/pdfs/tabela-odontologia-v2-nv.pdf | K7: — | N7: =IF(COUNT(F7,I7,L7)=0,"",MIN(F7,I7,L7)) -> 82.2 | O7: =IF(COUNT(F7,I7,L7)=0,"",AVERAGE(F7,I7,L7)) -> 99.205 | P7: =IF(COUNT(F7,I7,L7)=0,"",MEDIAN(F7,I7,L7)) -> 99.205 | Q7: =IF(COUNT(F7,I7,L7)=0,"",MAX(F7,I7,L7)) -> 116.21 | R7: Sem correspondente | S7: =IF(ISNUMBER(R7),ROUNDDOWN(R7*0.96,2),"—") -> — | T7: =IF(COUNT(F7,I7,L7)=0,"Sem cotação",ROUND(P7,2)) -> 99.21 | U7: =IF(AND(ISNUMBER(R7),ISNUMBER(T7)),T7/R7-1,"—") -> — | V7: =IF(ISNUMBER(T7),D7*T7,0) -> 136512.96
A8: 6 | B8: Aplicação de selante - Técnica invasiva (por elemento) | C8: Procedimento | D8: 1282 | E8: CIMINAS/MG – Termo de Contrato 741/2025 (Credenciamento 040/2025 – Sistema Carretas da Saúde), 30/09/2025 | F8: 80.7 | G8: https://ciminas.mg.gov.br | H8: Senado Federal/SIS – Tabela própria de credenciamento – Odontologia | I8: 109.36 | J8: https://www12.senado.leg.br/institucional/sis/pdfs/tabela-odontologia-v2-nv.pdf | K8: BC Saúde – Tabela de Procedimentos Odontológicos, Edital de Chamamento 2026 (selante por elemento) | L8: 43.9 | M8: https://www.bcb.gov.br/content/acessoinformacao/bcsaude_docs/Tabela_Procedimentos_Odontologicos_Edital_Chamamento_26.pdf | N8: =IF(COUNT(F8,I8,L8)=0,"",MIN(F8,I8,L8)) -> 43.9 | O8: =IF(COUNT(F8,I8,L8)=0,"",AVERAGE(F8,I8,L8)) -> 77.986667 | P8: =IF(COUNT(F8,I8,L8)=0,"",MEDIAN(F8,I8,L8)) -> 80.7 | Q8: =IF(COUNT(F8,I8,L8)=0,"",MAX(F8,I8,L8)) -> 109.36 | R8: Sem correspondente | S8: =IF(ISNUMBER(R8),ROUNDDOWN(R8*0.96,2),"—") -> — | T8: =IF(COUNT(F8,I8,L8)=0,"Sem cotação",ROUND(P8,2)) -> 80.7 | U8: =IF(AND(ISNUMBER(R8),ISNUMBER(T8)),T8/R8-1,"—") -> — | V8: =IF(ISNUMBER(T8),D8*T8,0) -> 103457.4
A9: 7 | B9: Aplicação tópica de flúor - por arcada | C9: Procedimento | D9: 14903 | E9: CIMINAS/MG – Termo de Contrato 741/2025 (Credenciamento 040/2025 – Sistema Carretas da Saúde), 30/09/2025 | F9: 66.5 | G9: https://ciminas.mg.gov.br | H9: Senado Federal/SIS – Tabela própria de credenciamento – Odontologia | I9: 90.1 | J9: https://www12.senado.leg.br/institucional/sis/pdfs/tabela-odontologia-v2-nv.pdf | K9: BC Saúde – Tabela de Procedimentos Odontológicos, Edital de Chamamento 2026 (verniz fluoretado, 4 hemiarcadas) | L9: 54.44 | M9: https://www.bcb.gov.br/content/acessoinformacao/bcsaude_docs/Tabela_Procedimentos_Odontologicos_Edital_Chamamento_26.pdf | N9: =IF(COUNT(F9,I9,L9)=0,"",MIN(F9,I9,L9)) -> 54.44 | O9: =IF(COUNT(F9,I9,L9)=0,"",AVERAGE(F9,I9,L9)) -> 70.346667 | P9: =IF(COUNT(F9,I9,L9)=0,"",MEDIAN(F9,I9,L9)) -> 66.5 | Q9: =IF(COUNT(F9,I9,L9)=0,"",MAX(F9,I9,L9)) -> 90.1 | R9: Sem correspondente | S9: =IF(ISNUMBER(R9),ROUNDDOWN(R9*0.96,2),"—") -> — | T9: =IF(COUNT(F9,I9,L9)=0,"Sem cotação",ROUND(P9,2)) -> 66.5 | U9: =IF(AND(ISNUMBER(R9),ISNUMBER(T9)),T9/R9-1,"—") -> — | V9: =IF(ISNUMBER(T9),D9*T9,0) -> 991049.5
A10: 8 | B10: Capeamento pulpar direto (excluindo restauração final) | C10: Procedimento | D10: 4471 | E10: CIMINAS/MG – Termo de Contrato 741/2025 (Credenciamento 040/2025 – Sistema Carretas da Saúde), 30/09/2025 | F10: 69.5 | G10: https://ciminas.mg.gov.br | H10: FioSaúde – Tabela Odontológica, vigência 02/04/2025 a 31/03/2026 | I10: 90 | J10: https://fiosaude.org.br/wp-content/uploads/2025/04/tabela_Odontologica_Fiosaude_2025-2026.pdf | K10: BC Saúde – Tabela de Reembolso Odontológico 2026 | L10: 82.42 | M10: https://www.bcb.gov.br/content/acessoinformacao/bcsaude_docs/Tabela_de_Reembolsos_procedimentos_odontologicos_2026.pdf | N10: =IF(COUNT(F10,I10,L10)=0,"",MIN(F10,I10,L10)) -> 69.5 | O10: =IF(COUNT(F10,I10,L10)=0,"",AVERAGE(F10,I10,L10)) -> 80.64 | P10: =IF(COUNT(F10,I10,L10)=0,"",MEDIAN(F10,I10,L10)) -> 82.42 | Q10: =IF(COUNT(F10,I10,L10)=0,"",MAX(F10,I10,L10)) -> 90 | R10: Sem correspondente | S10: =IF(ISNUMBER(R10),ROUNDDOWN(R10*0.96,2),"—") -> — | T10: =IF(COUNT(F10,I10,L10)=0,"Sem cotação",ROUND(P10,2)) -> 82.42 | U10: =IF(AND(ISNUMBER(R10),ISNUMBER(T10)),T10/R10-1,"—") -> — | V10: =IF(ISNUMBER(T10),D10*T10,0) -> 368499.82
A11: 9 | B11: Condicionamento em Odontologia | C11: Procedimento | D11: 905 | E11: CIMINAS/MG – Termo de Contrato 741/2025 (Credenciamento 040/2025 – Sistema Carretas da Saúde), 30/09/2025 | F11: 53.8 | G11: https://ciminas.mg.gov.br | H11: Senado Federal/SIS – Tabela própria de credenciamento – Odontologia | I11: 72.91 | J11: https://www12.senado.leg.br/institucional/sis/pdfs/tabela-odontologia-v2-nv.pdf | K11: FioSaúde – Tabela Odontológica, vigência 02/04/2025 a 31/03/2026 | L11: 73 | M11: https://fiosaude.org.br/wp-content/uploads/2025/04/tabela_Odontologica_Fiosaude_2025-2026.pdf | N11: =IF(COUNT(F11,I11,L11)=0,"",MIN(F11,I11,L11)) -> 53.8 | O11: =IF(COUNT(F11,I11,L11)=0,"",AVERAGE(F11,I11,L11)) -> 66.57 | P11: =IF(COUNT(F11,I11,L11)=0,"",MEDIAN(F11,I11,L11)) -> 72.91 | Q11: =IF(COUNT(F11,I11,L11)=0,"",MAX(F11,I11,L11)) -> 73 | R11: Sem correspondente | S11: =IF(ISNUMBER(R11),ROUNDDOWN(R11*0.96,2),"—") -> — | T11: =IF(COUNT(F11,I11,L11)=0,"Sem cotação",ROUND(P11,2)) -> 72.91 | U11: =IF(AND(ISNUMBER(R11),ISNUMBER(T11)),T11/R11-1,"—") -> — | V11: =IF(ISNUMBER(T11),D11*T11,0) -> 65983.55
A12: 10 | B12: Controle de biofilme (por sessão) | C12: Procedimento | D12: 905 | E12: CIMINAS/MG – Termo de Contrato 741/2025 (Credenciamento 040/2025 – Sistema Carretas da Saúde), 30/09/2025 | F12: 71 | G12: https://ciminas.mg.gov.br | H12: Senado Federal/SIS – Tabela própria de credenciamento – Odontologia | I12: 96.28 | J12: https://www12.senado.leg.br/institucional/sis/pdfs/tabela-odontologia-v2-nv.pdf | K12: STJ/Pró-Ser – Tabela Odontológica 2025 (vigência a partir de 01/03/2025) | L12: 48 | M12: https://www.stj.jus.br/sites/portalp/SiteAssets/Paginas/Sob-medida/Publico-interno/Pro-Ser/Informacoes-aos-credenciados/Tabela_Odontologica_PRECOS_2025.pdf | N12: =IF(COUNT(F12,I12,L12)=0,"",MIN(F12,I12,L12)) -> 48 | O12: =IF(COUNT(F12,I12,L12)=0,"",AVERAGE(F12,I12,L12)) -> 71.76 | P12: =IF(COUNT(F12,I12,L12)=0,"",MEDIAN(F12,I12,L12)) -> 71 | Q12: =IF(COUNT(F12,I12,L12)=0,"",MAX(F12,I12,L12)) -> 96.28 | R12: Sem correspondente | S12: =IF(ISNUMBER(R12),ROUNDDOWN(R12*0.96,2),"—") -> — | T12: =IF(COUNT(F12,I12,L12)=0,"Sem cotação",ROUND(P12,2)) -> 71 | U12: =IF(AND(ISNUMBER(R12),ISNUMBER(T12)),T12/R12-1,"—") -> — | V12: =IF(ISNUMBER(T12),D12*T12,0) -> 64255
A13: 11 | B13: Coroa provisória (por elemento) | C13: Procedimento | D13: 905 | E13: CIMINAS/MG – Termo de Contrato 741/2025 (Credenciamento 040/2025 – Sistema Carretas da Saúde), 30/09/2025 | F13: 101.25 | G13: https://ciminas.mg.gov.br | H13: FioSaúde – Tabela Odontológica, vigência 02/04/2025 a 31/03/2026 | I13: 104.5 | J13: https://fiosaude.org.br/wp-content/uploads/2025/04/tabela_Odontologica_Fiosaude_2025-2026.pdf | K13: STJ/Pró-Ser – Tabela Odontológica 2025 (vigência a partir de 01/03/2025) (sem pino) | L13: 167 | M13: https://www.stj.jus.br/sites/portalp/SiteAssets/Paginas/Sob-medida/Publico-interno/Pro-Ser/Informacoes-aos-credenciados/Tabela_Odontologica_PRECOS_2025.pdf | N13: =IF(COUNT(F13,I13,L13)=0,"",MIN(F13,I13,L13)) -> 101.25 | O13: =IF(COUNT(F13,I13,L13)=0,"",AVERAGE(F13,I13,L13)) -> 124.25 | P13: =IF(COUNT(F13,I13,L13)=0,"",MEDIAN(F13,I13,L13)) -> 104.5 | Q13: =IF(COUNT(F13,I13,L13)=0,"",MAX(F13,I13,L13)) -> 167 | R13: Sem correspondente | S13: =IF(ISNUMBER(R13),ROUNDDOWN(R13*0.96,2),"—") -> — | T13: =IF(COUNT(F13,I13,L13)=0,"Sem cotação",ROUND(P13,2)) -> 104.5 | U13: =IF(AND(ISNUMBER(R13),ISNUMBER(T13)),T13/R13-1,"—") -> — | V13: =IF(ISNUMBER(T13),D13*T13,0) -> 94572.5
A14: 12 | B14: Curativo de demora | C14: Procedimento | D14: 5083 | E14: CIMINAS/MG – Termo de Contrato 741/2025 (Credenciamento 040/2025 – Sistema Carretas da Saúde), 30/09/2025 | F14: 108.75 | G14: https://ciminas.mg.gov.br | H14: FioSaúde – Tabela Odontológica, vigência 02/04/2025 a 31/03/2026 | I14: 166 | J14: https://fiosaude.org.br/wp-content/uploads/2025/04/tabela_Odontologica_Fiosaude_2025-2026.pdf | K14: STJ/Pró-Ser – Tabela Odontológica 2025 (vigência a partir de 01/03/2025) | L14: 61 | M14: https://www.stj.jus.br/sites/portalp/SiteAssets/Paginas/Sob-medida/Publico-interno/Pro-Ser/Informacoes-aos-credenciados/Tabela_Odontologica_PRECOS_2025.pdf | N14: =IF(COUNT(F14,I14,L14)=0,"",MIN(F14,I14,L14)) -> 61 | O14: =IF(COUNT(F14,I14,L14)=0,"",AVERAGE(F14,I14,L14)) -> 111.91667 | P14: =IF(COUNT(F14,I14,L14)=0,"",MEDIAN(F14,I14,L14)) -> 108.75 | Q14: =IF(COUNT(F14,I14,L14)=0,"",MAX(F14,I14,L14)) -> 166 | R14: Sem correspondente | S14: =IF(ISNUMBER(R14),ROUNDDOWN(R14*0.96,2),"—") -> — | T14: =IF(COUNT(F14,I14,L14)=0,"Sem cotação",ROUND(P14,2)) -> 108.75 | U14: =IF(AND(ISNUMBER(R14),ISNUMBER(T14)),T14/R14-1,"—") -> — | V14: =IF(ISNUMBER(T14),D14*T14,0) -> 552776.25
A15: 13 | B15: Estabelecimento de vínculo com paciente idoso independente (por sessão) | C15: Procedimento | D15: 905 | E15: CIMINAS/MG – Termo de Contrato 741/2025 (Credenciamento 040/2025 – Sistema Carretas da Saúde), 30/09/2025 (análogo: vínculo com idoso/cuidador) | F15: 66.5 | G15: https://ciminas.mg.gov.br | H15: — | K15: — | N15: =IF(COUNT(F15,I15,L15)=0,"",MIN(F15,I15,L15)) -> 66.5 | O15: =IF(COUNT(F15,I15,L15)=0,"",AVERAGE(F15,I15,L15)) -> 66.5 | P15: =IF(COUNT(F15,I15,L15)=0,"",MEDIAN(F15,I15,L15)) -> 66.5 | Q15: =IF(COUNT(F15,I15,L15)=0,"",MAX(F15,I15,L15)) -> 66.5 | R15: Sem correspondente | S15: =IF(ISNUMBER(R15),ROUNDDOWN(R15*0.96,2),"—") -> — | T15: =IF(COUNT(F15,I15,L15)=0,"Sem cotação",ROUND(P15,2)) -> 66.5 | U15: =IF(AND(ISNUMBER(R15),ISNUMBER(T15)),T15/R15-1,"—") -> — | V15: =IF(ISNUMBER(T15),D15*T15,0) -> 60182.5
A16: 14 | B16: Estabelecimento de vínculo com paciente idoso parcialmente dependente (por sessão) | C16: Procedimento | D16: 905 | E16: CIMINAS/MG – Termo de Contrato 741/2025 (Credenciamento 040/2025 – Sistema Carretas da Saúde), 30/09/2025 | F16: 82.2 | G16: https://ciminas.mg.gov.br | H16: — | K16: — | N16: =IF(COUNT(F16,I16,L16)=0,"",MIN(F16,I16,L16)) -> 82.2 | O16: =IF(COUNT(F16,I16,L16)=0,"",AVERAGE(F16,I16,L16)) -> 82.2 | P16: =IF(COUNT(F16,I16,L16)=0,"",MEDIAN(F16,I16,L16)) -> 82.2 | Q16: =IF(COUNT(F16,I16,L16)=0,"",MAX(F16,I16,L16)) -> 82.2 | R16: Sem correspondente | S16: =IF(ISNUMBER(R16),ROUNDDOWN(R16*0.96,2),"—") -> — | T16: =IF(COUNT(F16,I16,L16)=0,"Sem cotação",ROUND(P16,2)) -> 82.2 | U16: =IF(AND(ISNUMBER(R16),ISNUMBER(T16)),T16/R16-1,"—") -> — | V16: =IF(ISNUMBER(T16),D16*T16,0) -> 74391
A17: 15 | B17: Estabelecimento de vínculo com paciente com necessidades especiais (por sessão) | C17: Procedimento | D17: 905 | E17: CIMINAS/MG – Termo de Contrato 741/2025 (Credenciamento 040/2025 – Sistema Carretas da Saúde), 30/09/2025 (análogo: idoso totalmente dependente) | F17: 107.6 | G17: https://ciminas.mg.gov.br | H17: — | K17: — | N17: =IF(COUNT(F17,I17,L17)=0,"",MIN(F17,I17,L17)) -> 107.6 | O17: =IF(COUNT(F17,I17,L17)=0,"",AVERAGE(F17,I17,L17)) -> 107.6 | P17: =IF(COUNT(F17,I17,L17)=0,"",MEDIAN(F17,I17,L17)) -> 107.6 | Q17: =IF(COUNT(F17,I17,L17)=0,"",MAX(F17,I17,L17)) -> 107.6 | R17: Sem correspondente | S17: =IF(ISNUMBER(R17),ROUNDDOWN(R17*0.96,2),"—") -> — | T17: =IF(COUNT(F17,I17,L17)=0,"Sem cotação",ROUND(P17,2)) -> 107.6 | U17: =IF(AND(ISNUMBER(R17),ISNUMBER(T17)),T17/R17-1,"—") -> — | V17: =IF(ISNUMBER(T17),D17*T17,0) -> 97378
A18: 16 | B18: Estabelecimento de vínculo com paciente idoso totalmente dependente (por sessão) | C18: Procedimento | D18: 905 | E18: CIMINAS/MG – Termo de Contrato 741/2025 (Credenciamento 040/2025 – Sistema Carretas da Saúde), 30/09/2025 | F18: 107.6 | G18: https://ciminas.mg.gov.br | H18: — | K18: — | N18: =IF(COUNT(F18,I18,L18)=0,"",MIN(F18,I18,L18)) -> 107.6 | O18: =IF(COUNT(F18,I18,L18)=0,"",AVERAGE(F18,I18,L18)) -> 107.6 | P18: =IF(COUNT(F18,I18,L18)=0,"",MEDIAN(F18,I18,L18)) -> 107.6 | Q18: =IF(COUNT(F18,I18,L18)=0,"",MAX(F18,I18,L18)) -> 107.6 | R18: Sem correspondente | S18: =IF(ISNUMBER(R18),ROUNDDOWN(R18*0.96,2),"—") -> — | T18: =IF(COUNT(F18,I18,L18)=0,"Sem cotação",ROUND(P18,2)) -> 107.6 | U18: =IF(AND(ISNUMBER(R18),ISNUMBER(T18)),T18/R18-1,"—") -> — | V18: =IF(ISNUMBER(T18),D18*T18,0) -> 97378
A19: 17 | B19: Estabelecimento de vínculo com paciente idoso, com cuidador de paciente idoso ou com cuidador de paciente com necessidades especiais | C19: Procedimento | D19: 905 | E19: CIMINAS/MG – Termo de Contrato 741/2025 (Credenciamento 040/2025 – Sistema Carretas da Saúde), 30/09/2025 | F19: 66.5 | G19: https://ciminas.mg.gov.br | H19: — | K19: — | N19: =IF(COUNT(F19,I19,L19)=0,"",MIN(F19,I19,L19)) -> 66.5 | O19: =IF(COUNT(F19,I19,L19)=0,"",AVERAGE(F19,I19,L19)) -> 66.5 | P19: =IF(COUNT(F19,I19,L19)=0,"",MEDIAN(F19,I19,L19)) -> 66.5 | Q19: =IF(COUNT(F19,I19,L19)=0,"",MAX(F19,I19,L19)) -> 66.5 | R19: Sem correspondente | S19: =IF(ISNUMBER(R19),ROUNDDOWN(R19*0.96,2),"—") -> — | T19: =IF(COUNT(F19,I19,L19)=0,"Sem cotação",ROUND(P19,2)) -> 66.5 | U19: =IF(AND(ISNUMBER(R19),ISNUMBER(T19)),T19/R19-1,"—") -> — | V19: =IF(ISNUMBER(T19),D19*T19,0) -> 60182.5
A20: 18 | B20: Estabilização do paciente por meio de contenção física e/ou mecânica | C20: Procedimento | D20: 905 | E20: CIMINAS/MG – Termo de Contrato 741/2025 (Credenciamento 040/2025 – Sistema Carretas da Saúde), 30/09/2025 | F20: 107.6 | G20: https://ciminas.mg.gov.br | H20: — | K20: — | N20: =IF(COUNT(F20,I20,L20)=0,"",MIN(F20,I20,L20)) -> 107.6 | O20: =IF(COUNT(F20,I20,L20)=0,"",AVERAGE(F20,I20,L20)) -> 107.6 | P20: =IF(COUNT(F20,I20,L20)=0,"",MEDIAN(F20,I20,L20)) -> 107.6 | Q20: =IF(COUNT(F20,I20,L20)=0,"",MAX(F20,I20,L20)) -> 107.6 | R20: Sem correspondente | S20: =IF(ISNUMBER(R20),ROUNDDOWN(R20*0.96,2),"—") -> — | T20: =IF(COUNT(F20,I20,L20)=0,"Sem cotação",ROUND(P20,2)) -> 107.6 | U20: =IF(AND(ISNUMBER(R20),ISNUMBER(T20)),T20/R20-1,"—") -> — | V20: =IF(ISNUMBER(T20),D20*T20,0) -> 97378
A21: 19 | B21: Exodontia a retalho | C21: Procedimento | D21: 3092 | E21: CIMINAS/MG – Termo de Contrato 741/2025 (Credenciamento 040/2025 – Sistema Carretas da Saúde), 30/09/2025 | F21: 124.8 | G21: https://ciminas.mg.gov.br | H21: MPU/Plan-Assiste – Anexo V da Norma Complementar 50 (2026) | I21: 127.89 | J21: https://planassiste.mpu.mp.br/o-plan-assiste/normas/normas-cpmplementares/anexo_v_nc_50.pdf/@@download/file/Anexo_V_NC_50.pdf | K21: FioSaúde – Tabela Odontológica, vigência 02/04/2025 a 31/03/2026 | L21: 123.5 | M21: https://fiosaude.org.br/wp-content/uploads/2025/04/tabela_Odontologica_Fiosaude_2025-2026.pdf | N21: =IF(COUNT(F21,I21,L21)=0,"",MIN(F21,I21,L21)) -> 123.5 | O21: =IF(COUNT(F21,I21,L21)=0,"",AVERAGE(F21,I21,L21)) -> 125.39667 | P21: =IF(COUNT(F21,I21,L21)=0,"",MEDIAN(F21,I21,L21)) -> 124.8 | Q21: =IF(COUNT(F21,I21,L21)=0,"",MAX(F21,I21,L21)) -> 127.89 | R21: Sem correspondente | S21: =IF(ISNUMBER(R21),ROUNDDOWN(R21*0.96,2),"—") -> — | T21: =IF(COUNT(F21,I21,L21)=0,"Sem cotação",ROUND(P21,2)) -> 124.8 | U21: =IF(AND(ISNUMBER(R21),ISNUMBER(T21)),T21/R21-1,"—") -> — | V21: =IF(ISNUMBER(T21),D21*T21,0) -> 385881.6
A22: 20 | B22: Exodontia de dente decíduo | C22: Procedimento | D22: 10860 | E22: CIMINAS/MG – Termo de Contrato 741/2025 (Credenciamento 040/2025 – Sistema Carretas da Saúde), 30/09/2025 | F22: 68 | G22: https://ciminas.mg.gov.br | H22: FioSaúde – Tabela Odontológica, vigência 02/04/2025 a 31/03/2026 | I22: 70.5 | J22: https://fiosaude.org.br/wp-content/uploads/2025/04/tabela_Odontologica_Fiosaude_2025-2026.pdf | K22: BC Saúde – Tabela de Procedimentos Odontológicos, Edital de Chamamento 2026 | L22: 53.28 | M22: https://www.bcb.gov.br/content/acessoinformacao/bcsaude_docs/Tabela_Procedimentos_Odontologicos_Edital_Chamamento_26.pdf | N22: =IF(COUNT(F22,I22,L22)=0,"",MIN(F22,I22,L22)) -> 53.28 | O22: =IF(COUNT(F22,I22,L22)=0,"",AVERAGE(F22,I22,L22)) -> 63.926667 | P22: =IF(COUNT(F22,I22,L22)=0,"",MEDIAN(F22,I22,L22)) -> 68 | Q22: =IF(COUNT(F22,I22,L22)=0,"",MAX(F22,I22,L22)) -> 70.5 | R22: Sem correspondente | S22: =IF(ISNUMBER(R22),ROUNDDOWN(R22*0.96,2),"—") -> — | T22: =IF(COUNT(F22,I22,L22)=0,"Sem cotação",ROUND(P22,2)) -> 68 | U22: =IF(AND(ISNUMBER(R22),ISNUMBER(T22)),T22/R22-1,"—") -> — | V22: =IF(ISNUMBER(T22),D22*T22,0) -> 738480
A23: 21 | B23: Exodontia de dente permanente | C23: Procedimento | D23: 181 | E23: CIMINAS/MG – Termo de Contrato 741/2025 (Credenciamento 040/2025 – Sistema Carretas da Saúde), 30/09/2025 | F23: 104.25 | G23: https://ciminas.mg.gov.br | H23: FioSaúde – Tabela Odontológica, vigência 02/04/2025 a 31/03/2026 | I23: 99 | J23: https://fiosaude.org.br/wp-content/uploads/2025/04/tabela_Odontologica_Fiosaude_2025-2026.pdf | K23: MPU/Plan-Assiste – Anexo V da Norma Complementar 50 (2026) | L23: 98.49 | M23: https://planassiste.mpu.mp.br/o-plan-assiste/normas/normas-cpmplementares/anexo_v_nc_50.pdf/@@download/file/Anexo_V_NC_50.pdf | N23: =IF(COUNT(F23,I23,L23)=0,"",MIN(F23,I23,L23)) -> 98.49 | O23: =IF(COUNT(F23,I23,L23)=0,"",AVERAGE(F23,I23,L23)) -> 100.58 | P23: =IF(COUNT(F23,I23,L23)=0,"",MEDIAN(F23,I23,L23)) -> 99 | Q23: =IF(COUNT(F23,I23,L23)=0,"",MAX(F23,I23,L23)) -> 104.25 | R23: Sem correspondente | S23: =IF(ISNUMBER(R23),ROUNDDOWN(R23*0.96,2),"—") -> — | T23: =IF(COUNT(F23,I23,L23)=0,"Sem cotação",ROUND(P23,2)) -> 99 | U23: =IF(AND(ISNUMBER(R23),ISNUMBER(T23)),T23/R23-1,"—") -> — | V23: =IF(ISNUMBER(T23),D23*T23,0) -> 17919
A24: 22 | B24: Exodontia de permanente por indicação ortodôntica/protética | C24: Procedimento | D24: 2528 | E24: CIMINAS/MG – Termo de Contrato 741/2025 (Credenciamento 040/2025 – Sistema Carretas da Saúde), 30/09/2025 | F24: 124.8 | G24: https://ciminas.mg.gov.br | H24: FioSaúde – Tabela Odontológica, vigência 02/04/2025 a 31/03/2026 (análogo: exodontia simples de permanente) | I24: 99 | J24: https://fiosaude.org.br/wp-content/uploads/2025/04/tabela_Odontologica_Fiosaude_2025-2026.pdf | K24: MPU/Plan-Assiste – Anexo V da Norma Complementar 50 (2026) (análogo: exodontia simples de permanente) | L24: 98.49 | M24: https://planassiste.mpu.mp.br/o-plan-assiste/normas/normas-cpmplementares/anexo_v_nc_50.pdf/@@download/file/Anexo_V_NC_50.pdf | N24: =IF(COUNT(F24,I24,L24)=0,"",MIN(F24,I24,L24)) -> 98.49 | O24: =IF(COUNT(F24,I24,L24)=0,"",AVERAGE(F24,I24,L24)) -> 107.43 | P24: =IF(COUNT(F24,I24,L24)=0,"",MEDIAN(F24,I24,L24)) -> 99 | Q24: =IF(COUNT(F24,I24,L24)=0,"",MAX(F24,I24,L24)) -> 124.8 | R24: Sem correspondente | S24: =IF(ISNUMBER(R24),ROUNDDOWN(R24*0.96,2),"—") -> — | T24: =IF(COUNT(F24,I24,L24)=0,"Sem cotação",ROUND(P24,2)) -> 99 | U24: =IF(AND(ISNUMBER(R24),ISNUMBER(T24)),T24/R24-1,"—") -> — | V24: =IF(ISNUMBER(T24),D24*T24,0) -> 250272
A25: 23 | B25: Exodontia de raiz residual | C25: Procedimento | D25: 97 | E25: CIMINAS/MG – Termo de Contrato 741/2025 (Credenciamento 040/2025 – Sistema Carretas da Saúde), 30/09/2025 | F25: 104.25 | G25: https://ciminas.mg.gov.br | H25: STJ/Pró-Ser – Tabela Odontológica 2025 (vigência a partir de 01/03/2025) | I25: 113 | J25: https://www.stj.jus.br/sites/portalp/SiteAssets/Paginas/Sob-medida/Publico-interno/Pro-Ser/Informacoes-aos-credenciados/Tabela_Odontologica_PRECOS_2025.pdf | K25: MPU/Plan-Assiste – Anexo V da Norma Complementar 50 (2026) | L25: 100.45 | M25: https://planassiste.mpu.mp.br/o-plan-assiste/normas/normas-cpmplementares/anexo_v_nc_50.pdf/@@download/file/Anexo_V_NC_50.pdf | N25: =IF(COUNT(F25,I25,L25)=0,"",MIN(F25,I25,L25)) -> 100.45 | O25: =IF(COUNT(F25,I25,L25)=0,"",AVERAGE(F25,I25,L25)) -> 105.9 | P25: =IF(COUNT(F25,I25,L25)=0,"",MEDIAN(F25,I25,L25)) -> 104.25 | Q25: =IF(COUNT(F25,I25,L25)=0,"",MAX(F25,I25,L25)) -> 113 | R25: Sem correspondente | S25: =IF(ISNUMBER(R25),ROUNDDOWN(R25*0.96,2),"—") -> — | T25: =IF(COUNT(F25,I25,L25)=0,"Sem cotação",ROUND(P25,2)) -> 104.25 | U25: =IF(AND(ISNUMBER(R25),ISNUMBER(T25)),T25/R25-1,"—") -> — | V25: =IF(ISNUMBER(T25),D25*T25,0) -> 10112.25
